File: dados_as_spin_orb.vms
VAMAS Surface Chemical Analysis Standard Data Transfer Format 1988 May 4
Not Specified
Not Specified
Not Specified
Not Specified
5
Casa Info Follows CasaXPS Version 2.3.25PR1.0
0
Conversion string = c:\users\gonca\onedrive\ambiente de trabalho\dados_as.dat
SourceAnalyserAngle: Not Specified
CasaRowLabel:dados_as.dat
NORM
REGULAR
0
1
Data Set
d
0
0
0
0
1
dados_as.dat
dados_as.dat
0
0
0
0
0
0
0
16
Casa Info Follows
0
1
annot comps v2315 Display 0.05 0.2 RGB(0,0,0) Font(35,18,0,0,Times New Roman)

1
CASA region (*108 - 96*) (*Tougaard*) 1380.3546 1389.0874 1 2 0 0 0 -450 0 0 (*NoTag*) 0 0 0
8
CASA comp (*SiO2 3/2*) (*SGL(10)*) Area 224.58636 0 400 -1 1 MFWHM 1.3488704 0.216 2 -1 1 Position 1383.7643 1383.6 1385.1 -1 -3.9 RSF 1 MASS 0 INDEX -1 (*NoTag*) CONST (**) UNCORRECTEDRSF 0
CASA comp (*SiO2 1/2*) (*SGL(10)*) Area 112.29318 1e-020 2888.6401 0 0.5 MFWHM 1.3488704 0.248 6.2 0 1 Position 1383.1643 0 0 0 -0.6 RSF 1 MASS 0 INDEX -1 (*NoTag*) CONST (**) UNCORRECTEDRSF 0
CASA comp (*Si 3/2*) (*SGL(50)*) Area 9.6712327 1e-020 2888.6401 -1 1 MFWHM 0.62952603 0 1 -1 1 Position 1387.7712 1380.5125 1388.563 -1 1 RSF 1 MASS 0 INDEX -1 (*NoTag*) CONST (**) UNCORRECTEDRSF 0
CASA comp (*Si 1/2*) (*SGL(50)*) Area 6.7844575 2 7 -1 0.5 MFWHM 0.62952603 0.2 0.7 2 1 Position 1387.1712 0 0 2 -0.6 RSF 1 MASS 0 INDEX -1 (*NoTag*) CONST (**) UNCORRECTEDRSF 0
CASA comp (*Si 1+ 3/2*) (*SGL(50)*) Area 6.4967439 1e-020 232.74289 -1 1 MFWHM 1 0.2413 1 -1 1 Position 1386.4781 1386.1 1387.1 -1 -1 RSF 1 MASS 0 INDEX -1 (*NoTag*) CONST (**) UNCORRECTEDRSF 0
CASA comp (*Si 1+ 1/2*) (*SGL(50)*) Area 3.248372 1e-020 232.74289 4 0.5 MFWHM 1 0.24126443 6.0316108 4 1 Position 1385.8781 0 0 4 -0.6 RSF 1 MASS 0 INDEX -1 (*NoTag*) CONST (**) UNCORRECTEDRSF 0
CASA comp (*Si 3+ 3/2*) (*SGL(40)*) Area 35.680159 1e-020 419.10499 -1 1 MFWHM 1.2700948 0.20390241 5.0975602 -1 1 Position 1384.8805 1384.6 1385.6 -1 -2.48 RSF 1 MASS 0 INDEX -1 (*NoTag*) CONST (**) UNCORRECTEDRSF 0
CASA comp (*Si 3+ 1/2*) (*SGL(40)*) Area 17.84008 1e-020 419.10499 6 0.5 MFWHM 1.2700948 0.20390241 5.0975602 6 1 Position 1384.2805 0 0 6 -0.6 RSF 1 MASS 0 INDEX -1 (*NoTag*) CONST (**) UNCORRECTEDRSF 0
XPS
1
Al
1486.6
1e+037
1e+037
1e+037
1e+037
1e+037
FAT
1e+037
1e+037
1e+037
1e+037
1e+037
1e+037
1e+037
1e+037
108 - 96

-1
Binding Energy
eV
108
-0.02
1
Counts
d
pulse counting
1
1
1e+037
1e+037
1e+037
1e+037
1
PROPAGATION_CONVERGED
d
1
601
0
1
53.2658
53.1088
51.9862
51.7585
52.4101
52.6064
52.5593
52.3944
51.3267
52.0176
51.4445
52.4651
52.1824
52.0176
51.5387
50.3297
50.7379
50.0157
50.5888
51.0834
49.8979
48.8852
48.846
49.9686
48.2258
50.5103
50.683
50.4789
48.3828
48.5163
49.9529
49.372
49.9843
49.1757
49.9686
49.0265
47.7547
48.6654
48.477
48.2415
48.7675
49.0501
48.2964
48.1865
47.268
46.7106
47.9746
48.2493
48.1473
47.0325
46.9069
47.0796
47.0561
48.2493
47.6684
47.8882
47.0639
46.0119
46.0198
47.5663
47.8647
46.2474
46.5772
46.0669
46.5615
46.1532
46.64
45.8863
47.0561
46.326
47.1032
45.2583
46.2003
45.8392
45.117
44.748
45.8471
44.7637
44.8972
43.9708
43.6489
45.1327
44.2534
41.914
42.8953
42.8403
43.5155
42.7069
42.1259
41.8119
42.7147
43.3663
41.6627
42.1259
42.1809
41.3566
42.1259
41.6784
40.705
41.7648
40.4616
41.3409
41.6627
40.9562
40.6971
41.5057
42.4164
41.4037
40.3753
40.7128
40.5715
40.4067
41.3958
39.7551
39.5431
41.0111
38.7423
40.1711
40.1947
40.3988
40.9483
41.8276
41.7962
40.548
41.2938
41.8747
40.5715
40.2496
40.6579
40.4695
40.4616
40.7599
40.8384
40.3753
41.6627
39.7315
41.4194
40.2339
41.859
40.8777
41.2781
41.6078
41.3801
40.2575
42.5184
41.4822
41.5999
41.019
41.5921
42.7775
41.8355
42.1966
43.7353
42.0788
44.5674
44.1671
45.1484
45.7607
44.7951
45.5095
46.0119
46.6164
46.8598
46.9383
46.9147
49.1286
48.2572
48.32
48.7204
52.0882
52.0647
52.2531
53.4385
53.4778
54.8202
56.6808
58.0075
59.0674
58.6277
60.6532
62.5059
65.0573
66.3134
67.5852
67.9777
69.0061
72.7273
73.5123
76.629
76.103
80.2559
80.515
83.1685
85.9947
88.2399
91.2624
93.4919
96.1218
99.7095
101.743
102.905
107.788
110.002
113.888
117.201
117.883
122.743
124.635
127.877
130.664
135.484
137.761
142.668
144.717
152.693
155.652
156.225
159.727
162.09
167.75
171.824
173.065
178.929
181.661
183.38
189.151
190.399
194.654
196.852
200.542
201.829
205.433
210.771
214.539
218.857
218.928
220.011
223.913
228.984
227.359
229.926
230.523
237.164
236.01
237.847
240.163
239.417
240.485
241.867
242.754
243.735
240.108
241.985
240.807
238.994
240.053
243.735
237.926
240.689
232.038
232.611
236.466
233.687
233.208
227.752
225.389
222.241
223.159
218.747
216.36
212.2
213.44
206.861
205.024
200.581
197.841
194.191
191.317
189.103
187.934
181.857
177.971
173.073
172.146
168.213
166.306
160.7
157.803
155.645
152.952
148.171
145.808
142.997
140.36
134.723
134.425
131.959
127.336
125.553
123.764
120.992
118.763
113.903
112.789
110.787
107.827
104.506
104.687
101.036
100.275
99.5447
95.2347
94.3712
92.9031
87.4313
85.7277
84.7464
82.4148
81.8417
81.2451
79.1098
77.0451
76.1344
72.7901
71.7538
70.6861
70.8039
70.4742
67.593
67.0356
64.9553
65.2065
63.2124
63.5657
62.9769
61.9328
60.8965
58.5963
58.9182
57.6935
58.6042
56.3432
55.3933
54.726
55.5189
54.1608
52.1118
52.5122
52.4729
51.2875
51.578
50.4946
51.4131
49.8037
49.3484
49.0658
49.3484
47.9589
47.7783
47.8176
47.3701
49.3249
47.4643
48.108
47.1267
46.7813
46.4123
46.3731
45.9805
46.483
44.8893
45.4231
45.6979
44.6145
44.0964
44.5988
45.4231
44.5203
45.0463
44.8187
44.3555
44.5596
42.8168
43.1151
44.4261
44.4889
44.2927
42.9502
43.8687
44.9521
44.5203
43.7117
43.6411
43.8609
44.12
44.5596
43.3977
43.0915
43.908
44.591
44.4654
44.7323
44.7009
44.7166
43.4841
44.3084
44.4968
43.8295
43.8609
43.7039
43.9001
44.2142
44.3869
44.9992
45.0856
45.1719
44.8501
44.7323
46.4516
44.3241
46.3338
47.0875
46.3024
47.3622
46.64
45.957
47.0718
46.7185
47.1974
48.5712
46.6164
49.0501
46.9147
47.1346
47.7547
46.5693
47.0796
46.8598
46.7813
46.9069
46.1454
46.483
46.5379
46.4516
47.0247
45.9099
47.3387
47.2837
47.7076
46.8205
47.0247
47.48
48.1394
48.634
48.8617
47.4486
49.9607
48.9716
48.5241
49.8037
49.4112
47.8882
47.4643
46.6007
45.588
46.4437
46.3181
45.6116
45.4624
43.7039
43.8216
42.6048
42.754
43.437
40.2732
41.388
40.9797
40.7128
40.6579
40.7285
38.9936
38.3027
37.7767
37.5883
38.2478
38.3655
38.3341
37.9965
37.1644
37.7846
36.2302
37.4078
36.9838
36.4971
36.7405
36.8425
36.7876
37.1408
36.8033
35.9711
37.1408
35.0447
36.4971
35.296
35.9083
33.8829
35.7277
36.3165
36.2537
36.4186
35.4373
35.555
35.4765
34.8485
35.1861
35.2724
35.0369
36.0025
34.9662
35.6806
35.6492
35.0526
35.029
33.6081
33.8593
35.0133
34.9034
34.4481
35.5079
34.7386
35.1861
34.0634
34.2204
35.0604
33.4982
34.2204
34.2832
32.7916
35.139
32.9251
34.5266
33.8515
34.0634
33.6709
33.93
34.032
32.9016
33.5846
33.4825
34.2754
33.9143
33.0821
32.9644
33.7573
33.8593
33.0272
34.0634
34.2126
34.3304
33.4354
32.7131
33.8279
33.3804
34.3146
33.2234
32.3599
32.352
32.2107
32.3834
33.561
32.2735
33.0429
32.2892
32.3756
31.9202
32.4148
32.2186
33.3098
31.512
32.9094
32.6111
32.6032
32.4227
32.9487
32.9094
31.9752
31.9438
32.1715
33.1214
31.2843
30.8761
33.192
31.6141
31.3629
32.407
32.4227
31.0488
31.7161
32.2735
31.5984
31.4885
end of experiment